---
title: 异步-代码烧脑的原因
date: 2019-06-05 21:00:19
tags:
categories:
	- JavaScript
---

> 彻底搞定异步和回调之间不得不说的故事！

<!--more-->

## 异步和同步

**同步**：等待结果，然后在继续执行下一条语句

**异步**：不等结果

**注意**：异步一般伴随回调出现，但是异步不是回调，回调不一定是异步

使用 **setTimeout** 实现异步

```javascript
function sleep(seconds, fn) {
    setTimeout(fn, seconds * 1000)
}
console.log(1)
sleep(3, ()=> console.log('wake up'))
console.log(2)
```



## 经常遇到的异步

```javascript
let w = document.getElementsByTagNames('img')[0].width
console.log(w) // 宽度为0，way？
```

因为执行到这步的时候，图片才刚刚发起请求，因为请求图片是异步的，所以获取图片宽度的时候，还为获取到图片，当然宽度为空了

```javascript
let w = document.getElementsByTagNames('img')[0]
w.onload = function() {
    console.log(this.width) // 成功获取到宽度
}
```

因为 onload 在在加载图片结束才会调用的，所以可以成功解决问题



## 面试中常遇到的异步

```javascript
let liList = document.querySelectorAll('li') // 假设有6个li
for (var i = 0; i < liList.length; i++) {
    liList[i].onclick = function() {
        console.log(i) //  点击哪个都是6
    }
}
```

**原因**：var 会变量提升到循环外面且只会有一个 i，循环六次后 i 的值为5，然后 i++，i 为6，使用var为每个click绑定的都是变量 i，因为代码是同步执行的，所以在我们点击之前，i 已经为6了，所以我们点击哪个都是6

**解决办法**：使用立即执行函数 或 let，目的都是为了为每一个li，创建一个单独的 i



## 异步的形式

异步一般有两种形式：

1. 蠢的方法：轮询，每隔一段时间调一次，看看是否请求成功
2. 正规方法：回调，异步解决，通过回调来执行设置的请求成功函数

**注意**：请求接口不要用同步方法，因为这样会使整个 js 都会在等待请求结果，任何操作都将无效



## 回调的形式

1. Node.js 判断第一个参数是否为空来决定调用的方法

   ```javascript
   fs.readFile('./xxx', (error, content) => {
       if (error) {
           // 失败
       } else {
           // 成功
       }
   })
   ```

2. jQuery 的 success / error 

   ```javascript
   $.ajax({
   	url: '/xx',
   	success: () => {},
   	error: () => {}
   })
   ```

3. jQuery 的 done / fail / always  成功调用 done ，失败调用 fail ，不管成功失败都调用 always  

   ```javascript
   $.ajax({
   	url: '/xx'
   }).done(() => {}).fail(() => {}).always(() => {})
   ```

4. Promise 的 then

   ```javascript
   $.ajax({
   	url: '/xx'
   }).then(() => {}, () => {})
   ```

**总结**：有没有感觉到各种方法都有，根本记不住，非常乱，但是如果我们只用ES6的 Promise 是不是就会简单很多那，Promise 就是为了解决混乱而出的一种规范，本质上和上面几种方法区别不大



## 如何处理异常？

在有多个成功回调的情况下，如何处理异常？

1. 使用 then 中的 reject,每一层的resolve 和 reject 出错，都会抛给下一层的 reject
2. 使用 catch 处理



## 自己实现一个简易版 Promise

```javascript
function Promise1(fn) {
    let status = 'pending' // 记录状态
    let successArray = [] // 成功执行的函数队列
    let failArray = [] // 失败执行的函数队列
    
    function successNotify() { // 成功调用
        status = 'resolve'
        toDoThen.apply(undefined, arguments)
    }
    function failNotify() { // 失败调用
        status = 'reject'
        toDoThen.apply(undefined, arguments)
    }
    function toDoThen() { // 遍历执行
        if (status === 'resolve') {
            for (let i = 0; i < successArray.length; i++) {
                successArray[i].apply(undefined, arguments)
            }
        } else if (status === 'reject') {
            for (let i = 0; i < failArray.length; i++) {
                failArray[i].apply(undefined, arguments)
            }
        }
    }

    fn.call(undefined, successNotify, failNotify)

    return {
        then: function(successFn, failFn) {
            successArray.push(successFn) // 添加到成功队列
            failArray.push(failFn) // 添加到失败队列
            return undefined
        }
    }
}

let promise = new Promise1(function(x, y) {
    setTimeout(() => {
        x(101)
    }, 1000)
})

promise.then((z) => {
    console.log(z)
})
```